<?xml version="1.0"?>
<robot name="humanoid_robot">

  <material name="black"><color rgba="0.1 0.1 0.1 1.0"/></material>
  <material name="red"><color rgba="1 0 0 1"/></material>
  <material name="purple"><color rgba="0.5 0 0.7 1"/></material>
  <material name="green"><color rgba="0 1 0 1"/></material>
  <material name="skin"><color rgba="1 0.60 0.0 1"/></material>
  <material name="green_900"><color rgba="0.0 0.3 0.0 1.0"/></material>  

  <link name="body_base_link">
    <visual>
      <origin xyz="0 0 0.35" rpy="0 0 0"/> 
      <geometry><box size="0.7 0.08 0.7"/></geometry>
      <material name="black"/>
    </visual>
    <collision>
      <origin xyz="0 0 0.35" rpy="0 0 0"/>
      <geometry><box size="0.7 0.08 0.7"/></geometry>
    </collision>
    <inertial>
      <mass value="3"/>
      <inertia ixx="0.1" ixy="0.0" ixz="0.0" iyy="0.1" iyz="0.0" izz="0.1"/>
    </inertial>
  </link>

  <link name="head_link">
    <visual>
      <origin xyz="0 0 0" rpy="0 0 0"/>
      <geometry><box size="0.2 0.2 0.2"/></geometry>
      <material name="green_900"/>
    </visual>
    <collision>
      <origin xyz="0 0 0" rpy="0 0 0"/>
      <geometry><box size="0.2 0.2 0.2"/></geometry>
    </collision>
    <inertial>
      <mass value="0.8"/>
      <inertia ixx="0.005" ixy="0.0" ixz="0.0" iyy="0.005" iyz="0.0" izz="0.005"/>
    </inertial>
  </link>

  <joint name="body_to_head_joint" type="fixed">
    <parent link="body_base_link"/>
    <child link="head_link"/>
    <origin xyz="0 0 0.8" rpy="0 0 0"/>
  </joint>
  

  <link name="arm_base_link_right">
    <visual><geometry><box size="0.05 0.05 0.05"/></geometry><material name="red"/></visual>
    <inertial><mass value="0.05"/><inertia ixx="0.0000208" ixy="0.0" ixz="0.0" iyy="0.0000208" iyz="0.0" izz="0.0000208"/></inertial>
  </link>
  <link name="upper_arm_link_right">
    <visual><origin xyz="0.15 0 0" rpy="0 1.5708 0"/><geometry><cylinder radius="0.05" length="0.3"/></geometry><material name="purple"/></visual>
    <collision><origin xyz="0.15 0 0" rpy="0 1.5708 0"/><geometry><cylinder radius="0.05" length="0.3"/></geometry></collision>
    <inertial>
      <mass value="0.5"/>
      <inertia ixx="0.00168" ixy="0.0" ixz="0.0" iyy="0.000625" iyz="0.0" izz="0.00168"/>
    </inertial>
  </link>
  <link name="forearm_link_right">
    <visual><origin xyz="0.125 0 0" rpy="0 1.5708 0"/><geometry><cylinder radius="0.03" length="0.25"/></geometry><material name="green"/></visual>
    <collision><origin xyz="0.125 0 0" rpy="0 1.5708 0"/><geometry><cylinder radius="0.03" length="0.25"/></geometry></collision>
    <inertial><mass value="0.25"/><inertia ixx="0.00013" ixy="0.0" ixz="0.0" iyy="0.000112" iyz="0.0" izz="0.00013"/></inertial>
  </link>
  <link name="wrist_link_right">
    <visual><origin xyz="0.045 0 0" rpy="0 1.5708 0"/><geometry><cylinder radius="0.03" length="0.09"/></geometry><material name="black"/></visual>
    <collision><origin xyz="0.045 0 0" rpy="0 1.5708 0"/><geometry><cylinder radius="0.03" length="0.09"/></geometry></collision>
    <inertial><mass value="0.08"/><inertia ixx="0.00003" ixy="0.0" ixz="0.0" iyy="0.00001" iyz="0.0" izz="0.00003"/></inertial>
  </link>
  <link name="finger_left_link_right"><visual><geometry><box size="0.02 0.02 0.09"/></geometry><material name="skin"/></visual><collision><geometry><box size="0.02 0.02 0.09"/></geometry></collision><inertial><mass value="0.05"/><inertia ixx="0.00003" ixy="0.0" ixz="0.0" iyy="0.00003" iyz="0.0" izz="0.000003"/></inertial></link>
  <link name="finger_right_link_right"><visual><geometry><box size="0.02 0.02 0.09"/></geometry><material name="skin"/></visual><collision><geometry><box size="0.02 0.02 0.09"/></geometry></collision><inertial><mass value="0.05"/><inertia ixx="0.00003" ixy="0.0" ixz="0.0" iyy="0.00003" iyz="0.0" izz="0.000003"/></inertial></link>
  <link name="finger_center_link_right"><visual><geometry><box size="0.02 0.02 0.09"/></geometry><material name="skin"/></visual><collision><geometry><box size="0.02 0.02 0.09"/></geometry></collision><inertial><mass value="0.05"/><inertia ixx="0.00003" ixy="0.0" ixz="0.0" iyy="0.00003" iyz="0.0" izz="0.000003"/></inertial></link>

  <joint name="body_to_arm_joint_right" type="revolute">
    <parent link="body_base_link"/><child link="arm_base_link_right"/>
    <origin xyz="0.35 0.04 0.65" rpy="0 0 0"/>  
    <axis xyz="0 1 0"/>  
    <limit lower="-1.57" upper="1.180" effort="10" velocity="1"/>
  </joint>
  <joint name="shoulder_yaw_joint_right" type="revolute">
    <parent link="arm_base_link_right"/><child link="upper_arm_link_right"/><origin xyz="0 0 0" rpy="0 0 0"/> <axis xyz="0 0 1"/>
    <limit lower="-1.57" upper="-0.399" effort="10" velocity="1"/>
  </joint>
  <joint name="shoulder_pitch_joint_right" type="revolute">
    <parent link="upper_arm_link_right"/><child link="forearm_link_right"/><origin xyz="0.3 0 0" rpy="0 0 0"/> <axis xyz="0 1 0"/>
    <limit lower="-0.025" upper="1.73" effort="10" velocity="1"/>
  </joint>
  <joint name="elbow_joint_right" type="revolute">
    <parent link="forearm_link_right"/><child link="wrist_link_right"/><origin xyz="0.25 0 0" rpy="0 0 0"/> <axis xyz="0 1 0"/>
    <limit lower="0" upper="1.57" effort="10" velocity="1"/>
  </joint>
  <joint name="finger_left_joint_right" type="fixed">
    <parent link="wrist_link_right"/><child link="finger_left_link_right"/><origin xyz="0.09 0 0.04" rpy="0 -1.5708 0"/> 
  </joint>
  <joint name="finger_right_joint_right" type="fixed">
    <parent link="wrist_link_right"/><child link="finger_right_link_right"/><origin xyz="0.09 0 -0.04" rpy="0 -1.5708 0"/> 
  </joint>
  <joint name="finger_center_joint_right" type="prismatic">
    <parent link="wrist_link_right"/><child link="finger_center_link_right"/><origin xyz="0.09 0 0" rpy="0 -1.5708 0"/> 
    <axis xyz="1 0 0"/><limit lower="0.0" upper="0.03" effort="10" velocity="0.5"/>
  </joint>


  <link name="arm_base_link_left">
    <visual><geometry><box size="0.05 0.05 0.05"/></geometry><material name="red"/></visual>
    <inertial><mass value="0.05"/><inertia ixx="0.0000208" ixy="0.0" ixz="0.0" iyy="0.0000208" iyz="0.0" izz="0.0000208"/></inertial>
  </link>
  <link name="upper_arm_link_left">
    <visual><origin xyz="0.15 0 0" rpy="0 1.5708 0"/><geometry><cylinder radius="0.05" length="0.3"/></geometry><material name="purple"/></visual>
    <collision><origin xyz="0.15 0 0" rpy="0 1.5708 0"/><geometry><cylinder radius="0.05" length="0.3"/></geometry></collision>
    <inertial>
      <mass value="0.5"/>
      <inertia ixx="0.00168" ixy="0.0" ixz="0.0" iyy="0.000625" iyz="0.0" izz="0.00168"/>
    </inertial>
  </link>
  <link name="forearm_link_left">
    <visual><origin xyz="0.125 0 0" rpy="0 1.5708 0"/><geometry><cylinder radius="0.03" length="0.25"/></geometry><material name="green"/></visual>
    <collision><origin xyz="0.125 0 0" rpy="0 1.5708 0"/><geometry><cylinder radius="0.03" length="0.25"/></geometry></collision>
    <inertial><mass value="0.25"/><inertia ixx="0.00013" ixy="0.0" ixz="0.0" iyy="0.000112" iyz="0.0" izz="0.00013"/></inertial>
  </link>
  <link name="wrist_link_left">
    <visual><origin xyz="0.045 0 0" rpy="0 1.5708 0"/><geometry><cylinder radius="0.03" length="0.09"/></geometry><material name="black"/></visual>
    <collision><origin xyz="0.045 0 0" rpy="0 1.5708 0"/><geometry><cylinder radius="0.03" length="0.09"/></geometry></collision>
    <inertial><mass value="0.08"/><inertia ixx="0.00003" ixy="0.0" ixz="0.0" iyy="0.00001" iyz="0.0" izz="0.00003"/></inertial>
  </link>
  <link name="finger_left_link_left"><visual><geometry><box size="0.02 0.02 0.09"/></geometry><material name="skin"/></visual><collision><geometry><box size="0.02 0.02 0.09"/></geometry></collision><inertial><mass value="0.05"/><inertia ixx="0.00003" ixy="0.0" ixz="0.0" iyy="0.00003" iyz="0.0" izz="0.000003"/></inertial></link>
  <link name="finger_right_link_left"><visual><geometry><box size="0.02 0.02 0.09"/></geometry><material name="skin"/></visual><collision><geometry><box size="0.02 0.02 0.09"/></geometry></collision><inertial><mass value="0.05"/><inertia ixx="0.00003" ixy="0.0" ixz="0.0" iyy="0.00003" iyz="0.0" izz="0.000003"/></inertial></link>
  <link name="finger_center_link_left"><visual><geometry><box size="0.02 0.02 0.09"/></geometry><material name="skin"/></visual><collision><geometry><box size="0.02 0.02 0.09"/></geometry></collision><inertial><mass value="0.05"/><inertia ixx="0.00003" ixy="0.0" ixz="0.0" iyy="0.00003" iyz="0.0" izz="0.000003"/></inertial></link>

  <joint name="body_to_arm_joint_left" type="revolute">
    <parent link="body_base_link"/><child link="arm_base_link_left"/>
    <origin xyz="-0.35 0.04 0.65" rpy="0 0 3.14159"/> 
    <axis xyz="0 1 0"/> 
    <limit lower="-1.57" upper="1.180" effort="10" velocity="1"/>
  </joint>
  <joint name="shoulder_yaw_joint_left" type="revolute">
    <parent link="arm_base_link_left"/><child link="upper_arm_link_left"/><origin xyz="0 0 0" rpy="0 0 0"/> <axis xyz="0 0 1"/>
    <limit lower="1.57" upper="0.00" effort="10" velocity="1"/>
  </joint>
  <joint name="shoulder_pitch_joint_left" type="revolute">
    <parent link="upper_arm_link_left"/><child link="forearm_link_left"/><origin xyz="0.3 0 0" rpy="0 0 0"/> <axis xyz="0 1 0"/>
    <limit lower="-0.025" upper="1.57" effort="10" velocity="1"/>
  </joint>
  <joint name="elbow_joint_left" type="revolute">
    <parent link="forearm_link_left"/><child link="wrist_link_left"/><origin xyz="0.25 0 0" rpy="0 0 0"/> <axis xyz="0 1 0"/>
    <limit lower="0" upper="1.57" effort="10" velocity="1"/>
  </joint>
  <joint name="finger_left_joint_left" type="fixed">
    <parent link="wrist_link_left"/><child link="finger_left_link_left"/><origin xyz="0.09 0 0.04" rpy="0 -1.5708 0"/> 
  </joint>
  <joint name="finger_right_joint_left" type="fixed">
    <parent link="wrist_link_left"/><child link="finger_right_link_left"/><origin xyz="0.09 0 -0.04" rpy="0 -1.5708 0"/> 
  </joint>
  <joint name="finger_center_joint_left" type="prismatic">
    <parent link="wrist_link_left"/><child link="finger_center_link_left"/><origin xyz="0.09 0 0" rpy="0 -1.5708 0"/> 
    <axis xyz="1 0 0"/><limit lower="0.0" upper="0.03" effort="10" velocity="0.5"/>
  </joint>

</robot>
